<robot name="my_robot" xmlns:xacro="http://www.ros.org/wiki/xacro">
	<xacro:include filename="$(find my_robot)/urdf/my_robot.gazebo" />
  <link name="robot_footprint"></link>
  <gazebo reference = "chassis">
    <material>Gazebo/Green</material>
  </gazebo>
	
  <gazebo reference = "camera">
    <material>Gazebo/Red</material>
  </gazebo>
	

  <joint name="robot_footprint_joint" type="fixed">
    <origin xyz="0 0 0" rpy="0 0 0" />
    <parent link="robot_footprint"/>
    <child link="chassis" />
  </joint>

  <link name='chassis'>
    <pose>0 0 0 0 0 0</pose>
    <inertial>
      <mass value="5"/>
      <origin xyz="0.0 0 0" rpy=" 0 0 0"/>
      <inertia
          ixx="0.1" ixy="0" ixz="0"
          iyy="0.1" iyz="0"
          izz="0.1"
      />
    </inertial>
    <collision name='collision'>
      <origin xyz="0 0 0" rpy=" 0 0 0"/> 
      <geometry>
        <box size=".4 .25 .1"/>
      </geometry>
    </collision>
    <visual name='chassis'>
      <origin xyz="0 0 0" rpy=" 0 0 0"/>
      <geometry>
        <box size=".4 .25 .1"/>
      </geometry>
    </visual>
  </link>

  <joint type="continuous" name="left_front_wheel">
    <origin xyz="0.13 0.13 0" rpy="0 0 0"/>
    <child link="left_front_wheel"/>
    <parent link="chassis"/>
    <axis xyz="0 1 0" rpy="0 0 0"/>
    <limit effort="10000" velocity="1000"/>
    <dynamics damping="1.0" friction="1.0"/>
  </joint>

  <link name='left_front_wheel'>
    <pose>0 0 0 0 0 0</pose>
    <inertial>
      <mass value="0.5"/>
      <origin xyz="0.0 0 0" rpy=" 1.5707 0 0"/>
      <inertia
          ixx="0.1" ixy="0" ixz="0"
          iyy="0.1" iyz="0"
          izz="0.1"
      />
    </inertial>
    <visual name='visual'>
       <origin xyz="0 0 0" rpy=" 1.5707 0 0"/>
        <geometry>
          <cylinder radius="0.1" length="0.1" />
        </geometry>
    </visual>
    <collision name='collision'>
       <origin xyz="0 0 0" rpy=" 1.5707 0 0"/>
        <geometry>
          <cylinder radius="0.1" length="0.1" />
        </geometry>
    </collision>
  </link>
	
  <joint type="continuous" name="right_front_wheel">
    <origin xyz="0.13 -0.13 0" rpy="0 0 0"/>
    <child link="right_front_wheel"/>
    <parent link="chassis"/>
    <axis xyz="0 1 0" rpy="0 0 0"/>
    <limit effort="10000" velocity="1000"/>
    <dynamics damping="1.0" friction="1.0"/>
  </joint>

  <link name='right_front_wheel'>
    <pose>0 0 0 0 0 0</pose>
    <inertial>
      <mass value="0.5"/>
      <origin xyz="0 0 0" rpy=" 1.5707 0 0"/>
      <inertia
          ixx="0.1" ixy="0" ixz="0"
          iyy="0.1" iyz="0"
          izz="0.1"
      />
    </inertial>
    <visual name='visual'>
       <origin xyz="0 0 0" rpy=" 1.5707 0 0"/>
        <geometry>
          <cylinder radius="0.1" length="0.1" />
        </geometry>
      </visual>
    <collision name='collision'>
       <origin xyz="0 0 0" rpy=" 1.5707 0 0"/>
        <geometry>
          <cylinder radius="0.1" length="0.1" />
        </geometry>
    </collision>
  </link>
  
  <joint type="continuous" name="left_back_wheel">
    <origin xyz="-0.13 0.13 0" rpy="0 0 0"/>
    <child link="left_back_wheel"/>
    <parent link="chassis"/>
    <axis xyz="0 1 0" rpy="0 0 0"/>
    <limit effort="10000" velocity="1000"/>
    <dynamics damping="1.0" friction="1.0"/>
  </joint>

  <link name='left_back_wheel'>
    <pose>0 0 0 0 0 0</pose>
    <inertial>
      <mass value="0.5"/>
      <origin xyz="0.0 0 0" rpy=" 1.5707 0 0"/>
      <inertia
          ixx="0.1" ixy="0" ixz="0"
          iyy="0.1" iyz="0"
          izz="0.1"
      />
    </inertial>
    <visual name='visual'>
       <origin xyz="0 0 0" rpy=" 1.5707 0 0"/>
        <geometry>
          <cylinder radius="0.1" length="0.1" />
        </geometry>
      </visual>
    <collision name='collision'>
       <origin xyz="0 0 0" rpy=" 1.5707 0 0"/>
        <geometry>
          <cylinder radius="0.1" length="0.1" />
        </geometry>
    </collision>
  </link>
  
  <joint type="continuous" name="right_back_wheel">
    <origin xyz="-0.13 -0.13 0" rpy="0 0 0"/>
    <child link="right_back_wheel"/>
    <parent link="chassis"/>
    <axis xyz="0 1 0" rpy="0 0 0"/>
    <limit effort="10000" velocity="1000"/>
    <dynamics damping="1.0" friction="1.0"/>
  </joint>

  <link name='right_back_wheel'>
    <pose>0 0 0 0 0 0</pose>
    <inertial>
      <mass value="0.5"/>
      <origin xyz="0.0 0 0" rpy=" 1.5707 0 0"/>
      <inertia
          ixx="0.1" ixy="0" ixz="0"
          iyy="0.1" iyz="0"
          izz="0.1"
      />
    </inertial>
    <visual name='visual'>
       <origin xyz="0 0 0" rpy=" 1.5707 0 0"/>
        <geometry>
          <cylinder radius="0.1" length="0.1" />
        </geometry>
      </visual>
    <collision name='collision'>
       <origin xyz="0 0 0" rpy=" 1.5707 0 0"/>
        <geometry>
          <cylinder radius="0.1" length="0.1" />
        </geometry>
    </collision>
  </link>
	
  <joint name="camera_joint" type="fixed">
    <origin xyz="0.2 0 0" rpy="0 0 0" />
    <parent link="chassis"/>
    <child link="camera" />
  </joint>
	<link name='camera'>
		<pose> 0 0 0 0 0 0</pose>
		<inertial>
      <mass value="0.1"/>
      <origin xyz="0.0 0 0" rpy=" 0 0 0"/>
      <inertia
          ixx="1e-6" ixy="0" ixz="0"
          iyy="1e-6" iyz="0"
          izz="1e-6"
      />
    </inertial>
    <collision name='camera_collision'>
      <origin xyz="0 0 0" rpy=" 0 0 0"/> 
      <geometry>
        <box size=".05 .05 .05"/>
      </geometry>
    </collision>
    <visual name='camera_visual'>
      <origin xyz="0 0 0" rpy=" 0 0 0"/>
      <geometry>
        <box size=".05 .05 .05"/>
      </geometry>
    </visual>			
		<box_inertia m="0.1" x="0.05" y="0.05" z="0.05"/>
	</link>

  <joint name="hokuyo_joint" type="fixed">
    <origin xyz="0.15 0 0.1" rpy="0 0 0" />
    <parent link="chassis"/>
    <child link="hokuyo" />
  </joint>
	<link name='hokuyo'>
		<pose> 0 0 0 0 0 0</pose>
		<inertial>
      <mass value="1e-5"/>
      <origin xyz="0.0 0 0" rpy=" 0 0 0"/>
      <inertia
          ixx="1e-6" ixy="0" ixz="0"
          iyy="1e-6" iyz="0"
          izz="1e-6"
      />
    </inertial>
    <collision name='hokuyo_collision'>
      <origin xyz="0 0 0" rpy=" 0 0 0"/> 
      <geometry>
        <box size=".1 .1 .1"/>
      </geometry>
    </collision>
    <visual name='hokuyo_visual'>
			<origin xyz="0 0 0" rpy=" 0 0 0"/> 			
			<geometry>
				<mesh  filename = "package://my_robot/meshes/hokuyo.dae"/> 
			</geometry>
		</visual>
	</link>


</robot>
